Workbook

Sheet Sprint 1
A1: Project name: | C1: MOVIX | F1: Kết thúc đúng hạn
A2: Module name: | C2: Sprint 1 | F2: Muộn
A3: Start date: | C3: 46103 | F3: Trước thời hạn
A4: End date: | C4: 46117
B6: SPRINT 1 REPORT
B7: No | C7: Thành viên | D7: Thực tế | E7: Ước tính
B8: 1 | C8: Phạm Quốc Hiệu | D8: =SUMIF($E$16:$F$84,"Hiệu",$G$16:$G$84)+SUMIF($E$16:$F$84,"All team",$G$16:$G$84)/5+SUMIF($E$16:$F$84,"Hiệu, Vinh",$G$16:$G$84)/2 -> 44.8 | E8: =SUMIF($E$16:$F$84,"Hiệu",$H$16:$H$84)+SUMIF($E$16:$F$84,"All team",$H$16:$H$84)/5+SUMIF($E$16:$F$84,"Hiệu, Vinh",$H$16:$H$84)/2 -> 44
B9: 2 | C9: Nguyễn Tam Minh Thức | D9: =SUMIF($E$16:$F$84,"Thức",$G$16:$G$84)+SUMIF($E$16:$F$84,"All team",$G$16:$G$84)/5+SUMIF($E$16:$F$84,"Thức,Việt,Vinh,Tài",$G$16:$G$84)/4 -> 18.8 | E9: =SUMIF($E$16:$F$84,"Thức",$H$16:$H$84)+SUMIF($E$16:$F$84,"All team",$H$16:$H$84)/5+SUMIF($E$16:$F$84,"Thức,Việt,Vinh,Tài",$H$16:$H$84)/4 -> 20.5
B10: 3 | C10: Lý Thái Tài | D10: =SUMIF($E$16:$F$84,"Tài",$G$16:$G$84)+SUMIF($E$16:$F$84,"All team",$G$16:$G$84)/5+SUMIF($E$16:$F$84,"Thức,Việt,Vinh,Tài",$G$16:$G$84)/4 -> 21.8 | E10: =SUMIF($E$16:$F$84,"Tài",$H$16:$H$84)+SUMIF($E$16:$F$84,"All team",$H$16:$H$84)/5+SUMIF($E$16:$F$84,"Thức,Việt,Vinh,Tài",$H$16:$H$84)/4 -> 24.5
B11: 4 | C11: Hoàng Đình Vinh | D11: =SUMIF($E$16:$F$84,"Vinh",$G$16:$G$84)+SUMIF($E$16:$F$84,"All team",$G$16:$G$84)/5+SUMIF($E$16:$F$84,"Thức,Việt,Vinh,Tài",$G$16:$G$84)/4+SUMIF($E$16:$F$84,"Hiệu, Vinh",$G$16:$G$84)/2 -> 23.8 | E11: =SUMIF($E$16:$F$84,"Vinh",$H$16:$H$84)+SUMIF($E$16:$F$84,"All team",$H$16:$H$84)/5+SUMIF($E$16:$F$84,"Thức,Việt,Vinh,Tài",$H$16:$H$84)/4+SUMIF($E$16:$F$84,"Hiệu, Vinh",$H$16:$H$84)/2 -> 26.5
B12: 5 | C12: Doãn Thanh Việt | D12: =SUMIF($E$16:$F$84,"Việt",$G$16:$G$84)+SUMIF($E$16:$F$84,"All team",$G$16:$G$84)/5+SUMIF($E$16:$F$84,"Thức,Việt,Vinh,Tài",$G$16:$G$84)/4 -> 16.8 | E12: =SUMIF($E$16:$F$84,"Việt",$H$16:$H$84)+SUMIF($E$16:$F$84,"All team",$H$16:$H$84)/5+SUMIF($E$16:$F$84,"Thức,Việt,Vinh,Tài",$H$16:$H$84)/4 -> 18.5
B13: Tổng | D13: =SUM(D8:D12) -> 126 | E13: =SUM(E8:E12) -> 134
A15: Sprint | B15: Compoment | C15: Task name | E15: Responsible Member | G15: Thực tế | H15: Ước tính | I15: 46103 | J15: 46104 | K15: 46105 | L15: 46106 | M15: 46107 | N15: 46108 | O15: 46109 | P15: 46110 | Q15: 46111 | R15: 46112 | S15: 46113 | T15: 46114 | U15: 46115 | V15: 46116 | W15: 46117 | X15: 46118
A16: Sprint 1 | B16: Họp kế hoạch Sprint | E16: All team | G16: 10 | H16: 10 | I16: 1 | J16: 0 | K16: 0 | L16: 0 | M16: 0 | N16: 0 | O16: 0 | P16: 0 | Q16: 0 | R16: 0 | S16: 0 | T16: 0 | U16: 0 | V16: 0 | W16: 0 | X16: 0
B17: Tạo Sprint Backlog 1 | E17: Tài | G17: 4 | H17: 4 | I17: 4 | J17: 4 | K17: 0 | L17: 0 | M17: 0 | N17: 0 | O17: 0 | P17: 0 | Q17: 0 | R17: 0 | S17: 0 | T17: 0 | U17: 0 | V17: 0 | W17: 0 | X17: 0
B18: Tạo tài liệu kiểm thử cho Sprint | E18: Thức,Việt,Vinh,Tài | G18: 4 | H18: 4 | I18: 4 | J18: 4 | K18: 0 | L18: 0 | M18: 0 | N18: 0 | O18: 0 | P18: 0 | Q18: 0 | R18: 0 | S18: 0 | T18: 0 | U18: 0 | V18: 0 | W18: 0 | X18: 0
B19: User interface design | C19: Giao diện Đăng nhập | E19: Vinh | G19: 1 | H19: 1 | I19: 1 | J19: 1 | K19: 1 | L19: 0 | N19: 0 | O19: 0 | P19: 0 | Q19: 0 | R19: 0 | S19: 0 | T19: 0 | U19: 0 | V19: 0 | W19: 0 | X19: 0
C20: Giao diện Đăng ký | E20: Vinh | G20: 1 | H20: 1 | I20: 1 | J20: 1 | K20: 1 | L20: 0 | M20: 0 | N20: 0 | O20: 0 | P20: 0 | Q20: 0 | R20: 0 | S20: 0 | T20: 0 | U20: 0 | V20: 0 | W20: 0 | X20: 0
C21: Giao diện Danh sách phim | E21: Thức | G21: 1 | H21: 2 | I21: 2 | J21: 2 | K21: 1 | L21: 0 | M21: 0 | N21: 0 | O21: 0 | P21: 0 | Q21: 0 | R21: 0 | S21: 0 | T21: 0 | U21: 0 | V21: 0 | W21: 0 | X21: 0
L22: 1
C23: Giao diện Chi tiết phim | E23: Vinh | G23: 1 | H23: 2 | I23: 2 | J23: 2 | K23: 1 | L23: 0 | M23: 0 | N23: 0 | O23: 0 | P23: 0 | Q23: 0 | R23: 0 | S23: 0 | T23: 0 | U23: 0 | V23: 0 | W23: 0 | X23: 0
L24: 1
C25: Giao diện Tìm kiếm phim | E25: Thức | G25: 1 | H25: 1 | I25: 1 | J25: 1 | K25: 1 | L25: 0 | M25: 0 | N25: 0 | O25: 0 | P25: 0 | Q25: 0 | R25: 0 | S25: 0 | T25: 0 | U25: 0 | V25: 0 | W25: 0 | X25: 0
C26: Giao diện Quản lý phim | E26: Tài | G26: 2 | H26: 2 | I26: 2 | J26: 2 | K26: 2 | L26: 0 | M26: 0 | N26: 0 | O26: 0 | P26: 0 | Q26: 0 | R26: 0 | S26: 0 | T26: 0 | U26: 0 | V26: 0 | W26: 0 | X26: 0
C27: Giao diện Quản lý rạp chiếu | E27: Thức | G27: 2 | H27: 2 | I27: 2 | J27: 2 | K27: 2 | L27: 0 | M27: 0 | N27: 0 | O27: 0 | P27: 0 | Q27: 0 | R27: 0 | S27: 0 | T27: 0 | U27: 0 | V27: 0 | W27: 0 | X27: 0
C28: Review all user interfaces of sprint 1 | E28: All team | G28: 6 | H28: 10 | I28: 10 | J28: 10 | K28: 10 | L28: 6 | M28: 0 | N28: 0 | O28: 0 | P28: 0 | Q28: 0 | R28: 0 | S28: 0 | T28: 0 | U28: 0 | V28: 0 | W28: 0 | X28: 0
M29: 4
B30: Design test case | C30: Thiết kế trường kiểm thử cho Đăng nhập | E30: Việt | G30: 1 | H30: 1 | I30: 1 | J30: 1 | K30: 1 | L30: 1 | M30: 1 | N30: 0 | O30: 0 | P30: 0 | Q30: 0 | R30: 0 | S30: 0 | T30: 0 | U30: 0 | V30: 0 | W30: 0 | X30: 0
C31: Thiết kế trường kiểm thử cho Đăng ký | E31: Tài | G31: 1 | H31: 1 | I31: 1 | J31: 1 | L31: 1 | M31: 1 | N31: 0 | O31: 0 | P31: 0 | Q31: 0 | R31: 0 | S31: 0 | T31: 0 | U31: 0 | V31: 0 | W31: 0 | X31: 0
C32: Thiết kế trường kiểm thử cho Danh sách phim | E32: Thức | G32: 1 | H32: 1 | I32: 1 | J32: 1 | K32: 1 | L32: 1 | M32: 1 | N32: 0 | O32: 0 | P32: 0 | Q32: 0 | R32: 0 | S32: 0 | T32: 0 | U32: 0 | V32: 0 | W32: 0 | X32: 0
C33: Thiết kế trường kiểm thử cho Chi tiết phim | E33: Tài | G33: 1 | H33: 1 | I33: 1 | J33: 1 | K33: 1 | L33: 1 | M33: 1 | N33: 0 | O33: 0 | P33: 0 | Q33: 0 | R33: 0 | S33: 0 | T33: 0 | U33: 0 | V33: 0 | W33: 0 | X33: 0
C34: Thiết kế trường kiểm thử cho Tìm kiếm phim | E34: Việt | G34: 1 | H34: 1 | I34: 1 | J34: 1 | K34: 1 | L34: 1 | M34: 1 | N34: 0 | O34: 0 | P34: 0 | Q34: 0 | R34: 0 | S34: 0 | T34: 0 | U34: 0 | V34: 0 | W34: 0 | X34: 0
C35: Thiết kế trường kiểm thử cho Quản lý phim | E35: Vinh | G35: 2 | H35: 2 | I35: 2 | J35: 2 | K35: 2 | L35: 2 | M35: 2 | N35: 0 | O35: 0 | P35: 0 | Q35: 0 | R35: 0 | S35: 0 | T35: 0 | U35: 0 | V35: 0 | W35: 0 | X35: 0
C36: Thiết kế trường kiểm thử cho Quản lý rạp chiếu | E36: Vinh | G36: 2 | H36: 2 | I36: 2 | J36: 2 | K36: 2 | L36: 2 | M36: 2 | N36: 0 | O36: 0 | P36: 0 | Q36: 0 | R36: 0 | S36: 0 | T36: 0 | U36: 0 | V36: 0 | W36: 0 | X36: 0
C37: Review all test case of sprint 1 | E37: All team | G37: 8 | H37: 10 | I37: 10 | J37: 10 | K37: 10 | L37: 10 | M37: 10 | N37: 8 | O37: 0 | P37: 0 | Q37: 0 | R37: 0 | S37: 0 | T37: 0 | U37: 0 | V37: 0 | W37: 0 | X37: 0
O38: 2
B39: Coding | C39: Code back-end cho Đăng nhập | E39: Hiệu | G39: 2 | H39: 2 | I39: 2 | J39: 2 | K39: 2 | L39: 2 | M39: 2 | N39: 2 | O39: 2 | P39: 0 | Q39: 0 | R39: 0 | S39: 0 | T39: 0 | U39: 0 | V39: 0 | W39: 0 | X39: 0
C40: Code front-end cho Đăng nhập | E40: Hiệu | G40: 2 | H40: 2 | I40: 2 | J40: 2 | K40: 2 | L40: 2 | M40: 2 | N40: 2 | O40: 2 | P40: 0 | Q40: 0 | R40: 0 | S40: 0 | T40: 0 | U40: 0 | V40: 0 | W40: 0 | X40: 0
C41: Code back-end cho Đăng ký | E41: Hiệu | G41: 2 | H41: 2 | I41: 2 | J41: 2 | K41: 2 | L41: 2 | M41: 2 | N41: 2 | O41: 2 | P41: 0 | Q41: 0 | R41: 0 | S41: 0 | T41: 0 | U41: 0 | V41: 0 | W41: 0 | X41: 0
C42: Code front-end cho Đăng ký | E42: Hiệu | G42: 2 | H42: 2 | I42: 2 | J42: 2 | K42: 2 | L42: 2 | M42: 2 | N42: 2 | O42: 2 | P42: 0 | Q42: 0 | R42: 0 | S42: 0 | T42: 0 | U42: 0 | V42: 0 | W42: 0 | X42: 0
...

Sheet Sprint 2
A1: Project name: | C1: MOVIX | G1: Kết thúc đúng hạn
A2: Module name: | C2: Sprint 2 | G2: Muộn
A3: Start date: | C3: 46118 | G3: Trước thời hạn
A4: End date: | C4: 46133
B6: SPRINT 2 REPORT
B7: No | C7: Thành viên | D7: Thực tế | E7: Ước tính
B8: 1 | C8: Phạm Quốc Hiệu | D8: =SUMIF($D$16:$D$79,"Hiệu",$F$16:$F$79)+SUMIF($D$16:$D$79,"All team",$F$16:$F$79)/5+SUMIF($D$16:$D$79,"Hiệu,Thức",$F$16:$F$79)/2 -> 39.8 | E8: =SUMIF($D$16:$D$79,"Hiệu",$G$16:$G$79)+SUMIF($D$16:$D$79,"All team",$G$16:$G$79)/5+SUMIF($D$16:$D$79,"Hiệu,Thức",$G$16:$G$79)/2 -> 39
B9: 2 | C9: Nguyễn Tam Minh Thức | D9: =SUMIF($D$16:$D$79,"Thức",$F$16:$F$79)+SUMIF($D$16:$D$79,"All team",$F$16:$F$79)/5+SUMIF($D$16:$D$79,"Thức,Tài",$F$16:$F$79)/2+SUMIF($D$16:$D$79,"Hiệu,Thức",$F$16:$F$79)/2 -> 21.8 | E9: =SUMIF($D$16:$D$79,"Thức",$G$16:$G$79)+SUMIF($D$16:$D$79,"All team",$G$16:$G$79)/5+SUMIF($D$16:$D$79,"Thức,Tài",$G$16:$G$79)/2+SUMIF($D$16:$D$79,"Hiệu,Thức",$G$16:$G$79)/2 -> 21
B10: 3 | C10: Lý Thái Tài | D10: =SUMIF($D$16:$D$79,"Tài",$F$16:$F$79)+SUMIF($D$16:$D$79,"All team",$F$16:$F$79)/5+SUMIF($D$16:$D$79,"Thức,Tài",$F$16:$F$79)/2+SUMIF($D$16:$D$79,"Tài,Vinh",$F$16:$F$79)/2 -> 22.8 | E10: =SUMIF($D$16:$D$79,"Tài",$G$16:$G$79)+SUMIF($D$16:$D$79,"All team",$G$16:$G$79)/5+SUMIF($D$16:$D$79,"Thức,Tài",$G$16:$G$79)/2+SUMIF($D$16:$D$79,"Tài,Vinh",$G$16:$G$79)/2 -> 21
B11: 4 | C11: Hoàng Đình Vinh | D11: =SUMIF($D$16:$D$79,"Vinh",$F$16:$F$79)+SUMIF($D$16:$D$79,"All team",$F$16:$F$79)/5+SUMIF($D$16:$D$79,"Tài,Vinh",$F$16:$F$79)/2 -> 12.8 | E11: =SUMIF($D$16:$D$79,"Vinh",$G$16:$G$79)+SUMIF($D$16:$D$79,"All team",$G$16:$G$79)/5+SUMIF($D$16:$D$79,"Tài,Vinh",$G$16:$G$79)/2 -> 14
B12: 5 | C12: Doãn Thanh Việt | D12: =SUMIF($D$16:$D$79,"Việt",$F$16:$F$79)+SUMIF($D$16:$D$79,"All team",$F$16:$F$79)/5 -> 18.8 | E12: =SUMIF($D$16:$D$79,"Việt",$G$16:$G$79)+SUMIF($D$16:$D$79,"All team",$G$16:$G$79)/5 -> 20
B13: Tổng | D13: =SUM(D8:D12) -> 116 | E13: =SUM(E8:E12) -> 115
A15: Sprint | B15: Compoment | C15: Task name | D15: Responsible Member | F15: Thực tế | G15: Ước tính | H15: 46118 | I15: 46119 | J15: 46120 | K15: 46121 | L15: 46122 | M15: 46123 | N15: 46124 | O15: 46125 | P15: 46126 | Q15: 46127 | R15: 46128 | S15: 46129 | T15: 46130 | U15: 46131 | V15: 46132 | W15: 46133
A16: Sprint 2 | B16: Họp kế hoạch Sprint | D16: All team | F16: 10 | G16: 10 | H16: 10 | I16: 0 | J16: 0 | K16: 0 | L16: 0 | M16: 0 | N16: 0 | O16: 0 | P16: 0 | Q16: 0 | R16: 0 | S16: 0 | T16: 0 | U16: 0 | V16: 0 | W16: 0
B17: Tạo Sprint Backlog 2 | D17: Tài,Vinh | F17: 4 | G17: 4 | H17: 4 | I17: 4 | J17: 0 | K17: 0 | L17: 0 | M17: 0 | N17: 0 | O17: 0 | P17: 0 | Q17: 0 | R17: 0 | S17: 0 | T17: 0 | U17: 0 | V17: 0 | W17: 0
B18: Tạo tài liệu kiểm thử cho Sprint | D18: Thức,Tài | F18: 4 | G18: 4 | H18: 4 | I18: 4 | J18: 4 | K18: 0 | L18: 0 | M18: 0 | N18: 0 | O18: 0 | P18: 0 | Q18: 0 | R18: 0 | S18: 0 | T18: 0 | U18: 0 | V18: 0 | W18: 0
B19: User interface design | C19: Giao diện Quên mật khẩu | D19: Vinh | F19: 1 | G19: 1 | H19: 1 | I19: 1 | J19: 1 | K19: 1 | L19: 0 | M19: 0 | N19: 0 | O19: 0 | P19: 0 | Q19: 0 | R19: 0 | S19: 0 | T19: 0 | U19: 0 | V19: 0 | W19: 0
C20: Giao diện Quản lý thông tin cá nhân | D20: Việt | F20: 1 | G20: 1 | H20: 1 | I20: 1 | J20: 1 | K20: 1 | L20: 0 | M20: 0 | N20: 0 | O20: 0 | P20: 0 | Q20: 0 | R20: 0 | S20: 0 | T20: 0 | U20: 0 | V20: 0 | W20: 0
C21: Giao diện Đặt vé | D21: Thức | F21: 3 | G21: 1 | H21: 1 | I21: 1 | J21: 1 | K21: 1 | L21: 0 | M21: 0 | N21: 0 | O21: 0 | P21: 0 | Q21: 0 | R21: 0 | S21: 0 | T21: 0 | U21: 0 | V21: 0 | W21: 0
L22: 2
C23: Giao diện Thanh toán | D23: Việt | F23: 1 | G23: 1 | H23: 1 | I23: 1 | J23: 1 | K23: 1 | L23: 0 | M23: 0 | N23: 0 | O23: 0 | P23: 0 | Q23: 0 | R23: 0 | S23: 0 | T23: 0 | U23: 0 | V23: 0 | W23: 0
C24: Giao diện quản lý phòng chiếu | D24: Việt | F24: 1 | G24: 1 | H24: 1 | I24: 1 | J24: 1 | K24: 1 | L24: 1 | M24: 0 | N24: 0 | O24: 0 | P24: 0 | Q24: 0 | R24: 0 | S24: 0 | T24: 0 | U24: 0 | V24: 0 | W24: 0
C25: Giao diện quản lý suất chiếu | D25: Việt | F25: 1 | G25: 1 | H25: 1 | I25: 1 | J25: 1 | K25: 1 | L25: 1 | M25: 0 | N25: 0 | O25: 0 | P25: 0 | Q25: 0 | R25: 0 | S25: 0 | T25: 0 | U25: 0 | V25: 0 | W25: 0
C26: Giao diện quản lí đặt vé | D26: Tài | F26: 1 | G26: 1 | H26: 1 | I26: 1 | J26: 1 | K26: 1 | L26: 1 | M26: 0 | N26: 0 | O26: 0 | P26: 0 | Q26: 0 | R26: 0 | S26: 0 | T26: 0 | U26: 0 | V26: 0 | W26: 0
C27: Review all user interfaces of sprint 2 | D27: All team | F27: 8 | G27: 10 | H27: 10 | I27: 10 | J27: 10 | K27: 10 | L27: 8 | M27: 0 | N27: 0 | O27: 0 | P27: 0 | Q27: 0 | R27: 0 | S27: 0 | T27: 0 | U27: 0 | V27: 0 | W27: 0
M28: 2
B29: Design test case | C29: Thiết kế trường kiểm thử cho Quên mật khẩu | D29: Vinh | F29: 1 | G29: 1 | H29: 1 | I29: 1 | J29: 1 | K29: 1 | L29: 1 | M29: 0 | N29: 0 | O29: 0 | P29: 0 | Q29: 0 | R29: 0 | S29: 0 | T29: 0 | U29: 0 | V29: 0 | W29: 0
C30: Thiết kế trường kiểm thử cho Quản lý thông tin cá nhân | D30: Việt | F30: 1 | G30: 1 | H30: 1 | I30: 1 | J30: 1 | K30: 1 | L30: 1 | M30: 0 | N30: 0 | O30: 0 | P30: 0 | Q30: 0 | R30: 0 | S30: 0 | T30: 0 | U30: 0 | V30: 0 | W30: 0
C31: Thiết kế trường kiểm thử cho Đặt Vé | D31: Thức | F31: 2 | G31: 2 | H31: 2 | I31: 2 | J31: 2 | K31: 2 | L31: 2 | M31: 0 | N31: 0 | O31: 0 | P31: 0 | Q31: 0 | R31: 0 | S31: 0 | T31: 0 | U31: 0 | V31: 0 | W31: 0
C32: Thiết kế trường kiểm thử cho Thanh Toán | D32: Việt | F32: 1 | G32: 1 | H32: 1 | I32: 1 | J32: 1 | K32: 1 | L32: 1 | M32: 0 | N32: 0 | O32: 0 | P32: 0 | Q32: 0 | R32: 0 | S32: 0 | T32: 0 | U32: 0 | V32: 0 | W32: 0
C33: Thiết kế trường kiểm thử cho Quản lý phòng chiếu | D33: Thức | F33: 2 | G33: 2 | H33: 2 | I33: 2 | J33: 2 | K33: 2 | L33: 2 | M33: 2 | N33: 0 | O33: 0 | P33: 0 | Q33: 0 | R33: 0 | S33: 0 | T33: 0 | U33: 0 | V33: 0 | W33: 0
C34: Thiết kế trường kiểm thử cho Quản lý Suất chiếu | D34: Tài | F34: 2 | G34: 2 | H34: 2 | I34: 2 | J34: 2 | K34: 2 | L34: 2 | M34: 2 | N34: 0 | O34: 0 | P34: 0 | Q34: 0 | R34: 0 | S34: 0 | T34: 0 | U34: 0 | V34: 0 | W34: 0
C35: Thiết kế trường kiểm thử cho Quản lý đặt vé | D35: Tài | F35: 3 | G35: 2 | H35: 2 | I35: 2 | J35: 2 | K35: 2 | L35: 2 | M35: 2 | N35: 0 | O35: 0 | P35: 0 | Q35: 0 | R35: 0 | S35: 0 | T35: 0 | U35: 0 | V35: 0 | W35: 0
N36: 1
C37: Review all test case of sprint 2 | D37: All team | F37: 8 | G37: 10 | H37: 10 | I37: 10 | J37: 10 | K37: 10 | L37: 10 | M37: 8 | N37: 0 | O37: 0 | P37: 0 | Q37: 0 | R37: 0 | S37: 0 | T37: 0 | U37: 0 | V37: 0 | W37: 0
N38: 2
B39: Coding | C39: Code back-end cho Quên mật khẩu | D39: Hiệu | F39: 2 | G39: 2 | H39: 2 | I39: 2 | J39: 2 | K39: 2 | L39: 2 | M39: 2 | N39: 2 | O39: 0 | P39: 0 | Q39: 0 | R39: 0 | S39: 0 | T39: 0 | U39: 0 | V39: 0 | W39: 0
C40: Code front-end cho Quên mật khẩu | D40: Hiệu | F40: 1 | G40: 1 | H40: 1 | I40: 1 | J40: 1 | K40: 1 | L40: 1 | M40: 1 | N40: 1 | O40: 0 | P40: 0 | Q40: 0 | R40: 0 | S40: 0 | T40: 0 | U40: 0 | V40: 0 | W40: 0
C41: Code back-end cho Quản lý thông tin cá nhân, | D41: Hiệu | F41: 2 | G41: 2 | H41: 2 | I41: 2 | J41: 2 | K41: 2 | L41: 2 | M41: 2 | N41: 2 | O41: 0 | P41: 0 | Q41: 0 | R41: 0 | S41: 0 | T41: 0 | U41: 0 | V41: 0 | W41: 0
C42: Code front-end cho Quản lý thông tin cá nhân | D42: Hiệu | F42: 1 | G42: 1 | H42: 1 | I42: 1 | J42: 1 | K42: 1 | L42: 1 | M42: 1 | N42: 1 | O42: 0 | P42: 0 | Q42: 0 | R42: 0 | S42: 0 | T42: 0 | U42: 0 | V42: 0 | W42: 0
...

Sheet Sprint 3
A1: Project name: | C1: MOVIX | F1: Kết thúc
A2: Module name: | C2: Sprint 3 | F2: Tăng ca
A3: Start date: | C3: 46133 | F3: Muộn
A4: End date: | C4: 46149 | D4: S | F4: Chậm tiến độ
F5: Trước thời hạn
B6: SPRINT 3 REPORT
B7: No | C7: Thành viên | D7: Thực tế | E7: Ước tính
B8: 1 | C8: Phạm Quốc Hiệu | D8: =SUMIF($E$16:$E$78,"Hiệu",$G$16:$G$78)+SUMIF($E$16:$E$78,"All team",$G$16:$G$78)/5+SUMIF($E$16:$E$78,"Hiệu, Việt",$G$16:$G$78)/2+SUMIF($E$16:$E$78,"Hiệu, Tài",$G$16:$G$78)/2 -> 48.1 | E8: =SUMIF($E$16:$E$78,"Hiệu",$H$16:$H$78)+SUMIF($E$16:$E$78,"All team",$H$16:$H$78)/5+SUMIF($E$16:$E$78,"Hiệu, Việt",$H$16:$H$78)/2+SUMIF($E$16:$E$78,"Hiệu, Tài",$H$16:$H$78)/2 -> 47
B9: 2 | C9: Nguyễn Tam Minh Thức | D9: =SUMIF($E$16:$E$78,"Thức",$G$16:$G$78)+SUMIF($E$16:$E$78,"All team",$G$16:$G$78)/5+SUMIF($E$16:$E$78,"Thức,Việt,Vinh,Tài",$G$16:$G$78)/4 -> 16.1 | E9: =SUMIF($E$16:$E$78,"Thức",$H$16:$H$78)+SUMIF($E$16:$E$78,"All team",$H$16:$H$78)/5+SUMIF($E$16:$E$78,"Thức,Việt,Vinh,Tài",$H$16:$H$78)/4 -> 17.5
B10: 3 | C10: Lý Thái Tài | D10: =SUMIF($E$16:$E$78,"Tài",$G$16:$G$78)+SUMIF($E$16:$E$78,"All team",$G$16:$G$78)/5+SUMIF($E$16:$E$78,"Thức,Việt,Vinh,Tài",$G$16:$G$78)/4+SUMIF($E$16:$E$78,"Hiệu, Tài",$G$16:$G$78)/2 -> 16.1 | E10: =SUMIF($E$16:$E$78,"Tài",$H$16:$H$78)+SUMIF($E$16:$E$78,"All team",$H$16:$H$78)/5+SUMIF($E$16:$E$78,"Thức,Việt,Vinh,Tài",$H$16:$H$78)/4+SUMIF($E$16:$E$78,"Hiệu, Tài",$H$16:$H$78)/2 -> 15.5
B11: 4 | C11: Hoàng Đình Vinh | D11: =SUMIF($E$16:$E$78,"Vinh",$G$16:$G$78)+SUMIF($E$16:$E$78,"All team",$G$16:$G$78)/5+SUMIF($E$16:$E$78,"Thức,Việt,Vinh,Tài",$G$16:$G$78)/4 -> 16.1 | E11: =SUMIF($E$16:$E$78,"Vinh",$H$16:$H$78)+SUMIF($E$16:$E$78,"All team",$H$16:$H$78)/5+SUMIF($E$16:$E$78,"Thức,Việt,Vinh,Tài",$H$16:$H$78)/4 -> 16.5
B12: 5 | C12: Doãn Thanh Việt | D12: =SUMIF($E$16:$E$78,"Việt",$G$16:$G$78)+SUMIF($E$16:$E$78,"All team",$G$16:$G$78)/5+SUMIF($E$16:$E$78,"Thức,Việt,Vinh,Tài",$G$16:$G$78)/4+SUMIF($E$16:$E$78,"Hiệu, Việt",$G$16:$G$78)/2 -> 15.6 | E12: =SUMIF($E$16:$E$78,"Việt",$H$16:$H$78)+SUMIF($E$16:$E$78,"All team",$H$16:$H$78)/5+SUMIF($E$16:$E$78,"Thức,Việt,Vinh,Tài",$H$16:$H$78)/4+SUMIF($E$16:$E$78,"Hiệu, Việt",$H$16:$H$78)/2 -> 17.5
B13: Tổng | D13: =SUM(D8:D12) -> 112 | E13: =SUM(E8:E12) -> 114
A15: Sprint | B15: Compoment | C15: Task name | E15: Responsible Member | G15: Thực tế | H15: Ước tính | I15: 46133 | J15: 46134 | K15: 46135 | L15: 46136 | M15: 46137 | N15: 46138 | O15: 46139 | P15: 46140 | Q15: 46141 | R15: 46142 | S15: 46143 | T15: 46144 | U15: 46145 | V15: 46146 | W15: 46147 | X15: 46148 | Y15: 46149 | Z15: 46150
A16: Sprint 3 | B16: Họp kế hoạch Sprint | E16: All team | G16: 10 | H16: 10 | I16: 10 | J16: 0 | K16: 0 | L16: 0 | M16: 0 | N16: 0 | O16: 0 | P16: 0 | Q16: 0 | R16: 0 | S16: 0 | T16: 0 | U16: 0 | V16: 0 | W16: 0 | X16: 0 | Y16: 0 | Z16: 0
B17: Tạo Sprint Backlog 3 | E17: Việt | G17: 1 | H17: 2 | I17: 2 | J17: 1 | K17: 0 | L17: 0 | M17: 0 | N17: 0 | O17: 0 | P17: 0 | Q17: 0 | R17: 0 | S17: 0 | T17: 0 | U17: 0 | V17: 0 | W17: 0 | X17: 0 | Y17: 0 | Z17: 0
K18: 1
B19: Tạo tài liệu kiểm thử cho Sprint | E19: Thức,Việt,Vinh,Tài | G19: 2 | H19: 2 | I19: 2 | J19: 2 | K19: 0 | L19: 0 | M19: 0 | N19: 0 | O19: 0 | P19: 0 | Q19: 0 | R19: 0 | S19: 0 | T19: 0 | U19: 0 | V19: 0 | W19: 0 | X19: 0 | Y19: 0 | Z19: 0
B20: User interface design | C20: Giao diện Đánh giá và bình luận phim | E20: Tài | G20: 1 | H20: 1 | I20: 1 | J20: 1 | K20: 1 | L20: 0 | M20: 0 | N20: 0 | O20: 0 | P20: 0 | Q20: 0 | R20: 0 | S20: 0 | T20: 0 | U20: 0 | V20: 0 | W20: 0 | X20: 0 | Y20: 0 | Z20: 0
C21: Giao diện Xem lịch sử đặt vé | E21: Vinh | G21: 1 | H21: 1 | I21: 1 | J21: 1 | K21: 1 | L21: 0 | M21: 0 | N21: 0 | O21: 0 | P21: 0 | Q21: 0 | R21: 0 | S21: 0 | T21: 0 | U21: 0 | V21: 0 | W21: 0 | X21: 0 | Y21: 0 | Z21: 0
C22: Giao diện Xem sơ đồ phòng chiếu 3D | E22: Tài | G22: 1 | H22: 1 | I22: 1 | J22: 1 | K22: 1 | L22: 0 | M22: 0 | N22: 0 | O22: 0 | P22: 0 | Q22: 0 | R22: 0 | S22: 0 | T22: 0 | U22: 0 | V22: 0 | W22: 0 | X22: 0 | Y22: 0 | Z22: 0
C23: Giao diện Chatbot AI | E23: Vinh | G23: 1 | H23: 1 | I23: 1 | J23: 1 | K23: 1 | L23: 0 | M23: 0 | N23: 0 | O23: 0 | P23: 0 | Q23: 0 | R23: 0 | S23: 0 | T23: 0 | U23: 0 | V23: 0 | W23: 0 | X23: 0 | Y23: 0 | Z23: 0
C24: Giao diện Quản lý thành viên | E24: Việt | G24: 1 | H24: 1 | I24: 1 | J24: 1 | K24: 1 | L24: 1 | M24: 0 | N24: 0 | O24: 0 | P24: 0 | Q24: 0 | R24: 0 | S24: 0 | T24: 0 | U24: 0 | V24: 0 | W24: 0 | X24: 0 | Y24: 0 | Z24: 0
C25: Giao diện Quản lý bình luận | E25: Thức | G25: 1 | H25: 1 | I25: 1 | J25: 1 | K25: 1 | L25: 1 | M25: 0 | N25: 0 | O25: 0 | P25: 0 | Q25: 0 | R25: 0 | S25: 0 | T25: 0 | U25: 0 | V25: 0 | W25: 0 | X25: 0 | Y25: 0 | Z25: 0
C26: Giao diện Thống kê và báo cáo | E26: Tài | G26: 2 | H26: 1 | I26: 1 | J26: 1 | K26: 1 | L26: 1 | M26: 0 | N26: 0 | O26: 0 | P26: 0 | Q26: 0 | R26: 0 | S26: 0 | T26: 0 | U26: 0 | V26: 0 | W26: 0 | X26: 0 | Y26: 0 | Z26: 0
M27: 1
C28: Review all user interfaces of sprint 3 | E28: All team | G28: 8 | H28: 10 | I28: 10 | J28: 10 | K28: 10 | L28: 8 | M28: 0 | N28: 0 | O28: 0 | P28: 0 | Q28: 0 | R28: 0 | S28: 0 | T28: 0 | U28: 0 | V28: 0 | W28: 0 | X28: 0 | Y28: 0 | Z28: 0
M29: 2
B30: Design test case | C30: Thiết kế trường kiểm thử cho Đánh giá và bình luận phim | E30: Tài | G30: 1 | H30: 1 | I30: 1 | J30: 1 | K30: 1 | L30: 1 | M30: 1 | N30: 0 | O30: 0 | P30: 0 | Q30: 0 | R30: 0 | S30: 0 | T30: 0 | U30: 0 | V30: 0 | W30: 0 | X30: 0 | Y30: 0 | Z30: 0
C31: Thiết kế trường kiểm thử cho Xem lịch sử đặt vé | E31: Tài | G31: 2 | H31: 2 | I31: 2 | J31: 2 | K31: 2 | L31: 2 | M31: 2 | N31: 0 | O31: 0 | P31: 0 | Q31: 0 | R31: 0 | S31: 0 | T31: 0 | U31: 0 | V31: 0 | W31: 0 | X31: 0 | Y31: 0 | Z31: 0
C32: Thiết kế trường kiểm thử cho Xem sơ đồ phòng chiếu 3D | E32: Vinh | G32: 2 | H32: 2 | I32: 2 | J32: 2 | K32: 2 | L32: 2 | M32: 2 | N32: 0 | O32: 0 | P32: 0 | Q32: 0 | R32: 0 | S32: 0 | T32: 0 | U32: 0 | V32: 0 | W32: 0 | X32: 0 | Y32: 0 | Z32: 0
C33: Thiết kế trường kiểm thử cho Chatbot AI | E33: Thức | G33: 1 | H33: 1 | I33: 1 | J33: 1 | K33: 1 | L33: 1 | M33: 1 | N33: 1 | O33: 0 | P33: 0 | Q33: 0 | R33: 0 | S33: 0 | T33: 0 | U33: 0 | V33: 0 | W33: 0 | X33: 0 | Y33: 0 | Z33: 0
C34: Thiết kế trường kiểm thử cho Quản lý thành viên | E34: Việt | G34: 2 | H34: 1 | I34: 1 | J34: 1 | K34: 1 | L34: 1 | M34: 1 | N34: 1 | O34: 0 | P34: 0 | Q34: 0 | R34: 0 | S34: 0 | T34: 0 | U34: 0 | V34: 0 | W34: 0 | X34: 0 | Y34: 0 | Z34: 0
C35: Thiết kế trường kiểm thử cho Quản lý bình luận | E35: Thức | G35: 1 | H35: 1 | I35: 1 | J35: 1 | K35: 1 | L35: 1 | M35: 1 | N35: 1 | O35: 1 | P35: 0 | Q35: 0 | R35: 0 | S35: 0 | T35: 0 | U35: 0 | V35: 0 | W35: 0 | X35: 0 | Y35: 0 | Z35: 0
C36: Thiết kế trường kiểm thử cho Thống kê và báo cáo | E36: Vinh | G36: 1 | H36: 1 | I36: 1 | J36: 1 | K36: 1 | L36: 1 | M36: 1 | N36: 1 | O36: 1 | P36: 0 | Q36: 0 | R36: 0 | S36: 0 | T36: 0 | U36: 0 | V36: 0 | W36: 0 | X36: 0 | Y36: 0 | Z36: 0
C37: Review all test case of sprint 1 | E37: All team | G37: 7 | H37: 10 | I37: 10 | J37: 10 | K37: 10 | L37: 10 | M37: 10 | N37: 10 | O37: 7 | P37: 0 | Q37: 0 | R37: 0 | S37: 0 | T37: 0 | U37: 0 | V37: 0 | W37: 0 | X37: 0 | Y37: 0 | Z37: 0
P38: 3
B39: Coding | C39: Code back-end cho Đánh giá và bình luận phim | E39: Hiệu | G39: 3 | H39: 3 | I39: 3 | J39: 3 | K39: 3 | L39: 3 | M39: 3 | N39: 3 | O39: 3 | P39: 3 | Q39: 0 | R39: 0 | S39: 0 | T39: 0 | U39: 0 | V39: 0 | W39: 0 | X39: 0 | Y39: 0 | Z39: 0
C40: Code front-end cho Đánh giá và bình luận phim | E40: Hiệu | G40: 2 | H40: 2 | I40: 2 | J40: 2 | K40: 2 | L40: 2 | M40: 2 | N40: 2 | O40: 2 | P40: 2 | Q40: 0 | R40: 0 | S40: 0 | T40: 0 | U40: 0 | V40: 0 | W40: 0 | X40: 0 | Y40: 0 | Z40: 0
C41: Code back-end cho cho Xem lịch sử đặt vé | E41: Hiệu | G41: 3 | H41: 3 | I41: 3 | J41: 3 | K41: 3 | L41: 3 | M41: 3 | N41: 3 | O41: 3 | P41: 3 | Q41: 0 | R41: 0 | S41: 0 | T41: 0 | U41: 0 | V41: 0 | W41: 0 | X41: 0 | Y41: 0 | Z41: 0
...

Sheet Total
A1: SPRINT BACKLOG REPORT
B2: Hiệu | D2: Thức | F2: Tài | H2: Vinh | J2: Việt
B3: Thực tế | C3: Ước tính | D3: Thực tế | E3: Ước tính | F3: Thực tế | G3: Ước tính | H3: Thực tế | I3: Ước tính | J3: Thực tế | K3: Ước tính
A4: Sprint 1 | B4: ='Sprint 1'!$D$8 -> 44.8 | C4: ='Sprint 1'!$E$8 -> 44 | D4: ='Sprint 1'!$D$9 -> 18.8 | E4: ='Sprint 1'!$E$9 -> 20.5 | F4: ='Sprint 1'!$D$10 -> 21.8 | G4: ='Sprint 1'!$E$10 -> 24.5 | H4: ='Sprint 1'!$D$11 -> 23.8 | I4: ='Sprint 1'!$E$11 -> 26.5 | J4: ='Sprint 1'!$D$12 -> 16.8 | K4: ='Sprint 1'!$E$12 -> 18.5
A5: Sprint 2 | B5: ='Sprint 2'!D8 -> 39.8 | C5: ='Sprint 2'!$E$8 -> 39 | D5: ='Sprint 2'!D9 -> 21.8 | E5: ='Sprint 2'!$E$9 -> 21 | F5: ='Sprint 2'!D10 -> 22.8 | G5: ='Sprint 2'!$E$10 -> 21 | H5: ='Sprint 2'!D11 -> 12.8 | I5: ='Sprint 2'!$E$11 -> 14 | J5: ='Sprint 2'!D12 -> 18.8 | K5: ='Sprint 2'!$E$12 -> 20
A6: Sprint 3 | B6: ='Sprint 3'!$D$8 -> 48.1 | C6: ='Sprint 3'!$E$8 -> 47 | D6: ='Sprint 3'!$D$9 -> 16.1 | E6: ='Sprint 3'!$E$9 -> 17.5 | F6: ='Sprint 3'!$D$10 -> 16.1 | G6: ='Sprint 3'!$E$10 -> 15.5 | H6: ='Sprint 3'!$D$11 -> 16.1 | I6: ='Sprint 3'!$E$11 -> 16.5 | J6: ='Sprint 3'!$D$12 -> 15.6 | K6: ='Sprint 3'!$E$12 -> 17.5
A7: Tổng | B7: =SUM(B4:B6) -> 132.7 | C7: =SUM(C4:C6) -> 130 | D7: =SUM(D4:D6) -> 56.7 | E7: =SUM(E4:E6) -> 59 | F7: =SUM(F4:F6) -> 60.7 | G7: =SUM(G4:G6) -> 61 | H7: =SUM(H4:H6) -> 52.7 | I7: =SUM(I4:I6) -> 57 | ... K7: =SUM(K4:K6) -> 56
E10: FINAL TOTAL
E11: Thực tế | F11: =SUMIF($B$3:$K$3,"Thực tế",$B$7:$K$7) -> 354
E12: Ước tính | F12: =SUMIF($B$3:$K$3,"Ước tính",$B$7:$K$7) -> 363
